Workbook

Sheet Raw_Data
A1: Raw Investment Data
A2: ApexNova Technologies Ltd. | FY2025-26 | 150 realistic corporate investment records
A4: Investment_ID | B4: Investment_Name | C4: Investment_Category | D4: Department | E4: Region | F4: Start_Date | G4: End_Date | H4: Initial_Investment | I4: Additional_Investment | J4: Budgeted_Investment | K4: Expected_Revenue | L4: Actual_Revenue | M4: Expected_Cost_Savings | N4: Actual_Cost_Savings | O4: Investment_Status | P4: Risk_Level
A5: INV-001 | B5: ERP Cloud Migration – Central | C5: Technology | D5: HR | E5: Central | F5: 45925 | G5: 46643 | H5: 33630000 | I5: 2620000 | J5: 36270000 | K5: 44295443 | L5: 44650966 | M5: 1555987.9 | N5: 1252518.6 | O5: Active | P5: Low
A6: INV-002 | B6: Brand Repositioning – South | C6: Marketing | D6: Supply Chain | E6: South | F6: 46045 | G6: 46699 | H6: 7490000 | I6: 530000 | J6: 8460000 | K6: 9041768 | L6: 9120793.5 | M6: 356078.55 | N6: 321968.96 | O6: Completed | P6: High
A7: INV-003 | B7: Premium Product Line – West | C7: Product Development | D7: Operations | E7: West | F7: 45874 | G7: 46411 | H7: 34110000 | I7: 1430000 | J7: 36480000 | K7: 40821273 | L7: 38626369 | M7: 3556096.6 | N7: 3953686.5 | O7: Cancelled | P7: Medium
A8: INV-004 | B8: Tier-2 City Expansion – North | C8: Expansion | D8: Finance | E8: North | F8: 45405 | G8: 45961 | H8: 22460000 | I8: 630000 | J8: 24320000 | K8: 26063425 | L8: 25024555 | M8: 2593160.2 | N8: 2841181.8 | O8: On Hold | P8: Low
A9: INV-005 | B9: Automated Packaging Line – East | C9: Equipment | D9: Sales | E9: East | F9: 45496 | G9: 45852 | H9: 27540000 | I9: 3750000 | J9: 30250000 | K9: 33855626 | L9: 34288710 | M9: 2466361.7 | N9: 2482722.1 | O9: Active | P9: High
A10: INV-006 | B10: RPA Finance Rollout – Central | C10: Automation | D10: IT | E10: Central | F10: 45945 | G10: 46142 | H10: 17840000 | I10: 1060000 | J10: 17490000 | K10: 21918904 | L10: 21989015 | M10: 1956666.5 | N10: 1619526.8 | O10: Completed | P10: Medium
A11: INV-007 | B11: Leadership Development – South | C11: Training | D11: Product | E11: South | F11: 46018 | G11: 46874 | H11: 11690000 | I11: 1540000 | J11: 12170000 | K11: 13083912 | L11: 11052861 | M11: 2448716 | N11: 2215229.6 | O11: Cancelled | P11: Low
A12: INV-008 | B12: Plant Utility Upgrade – West | C12: Infrastructure | D12: Marketing | E12: West | F12: 46029 | G12: 46456 | H12: 16360000 | I12: 1260000 | J12: 16370000 | K12: 18270392 | L12: 18724577 | M12: 976615.75 | N12: 913794.83 | O12: On Hold | P12: High
A13: INV-009 | B13: ERP Cloud Migration – North | C13: Technology | D13: HR | E13: North | F13: 46028 | G13: 46394 | H13: 19340000 | I13: 1500000 | J13: 21430000 | K13: 22689717 | L13: 25582766 | M13: 1907747.4 | N13: 1520321.6 | O13: Active | P13: Medium
A14: INV-010 | B14: Brand Repositioning – East | C14: Marketing | D14: Supply Chain | E14: East | F14: 45619 | G14: 45899 | H14: 9210000 | I14: 300000 | J14: 9850000 | K14: 10046184 | L14: 10085255 | M14: 1515144.5 | N14: 1663386.1 | O14: Completed | P14: Low
A15: INV-011 | B15: Premium Product Line – Central | C15: Product Development | D15: Operations | E15: Central | F15: 45509 | G15: 45881 | H15: 20670000 | I15: 3360000 | J15: 25610000 | K15: 25230103 | L15: 21668941 | M15: 3686889.1 | N15: 3871983.4 | O15: Cancelled | P15: High
A16: INV-012 | B16: Tier-2 City Expansion – South | C16: Expansion | D16: Finance | E16: South | F16: 45969 | G16: 46674 | H16: 26920000 | I16: 2850000 | J16: 30060000 | K16: 29157879 | L16: 30935879 | M16: 5375701 | N16: 4111287.5 | O16: On Hold | P16: Medium
... A154: INV-150 | B154: RPA Finance Rollout – East | C154: Automation | D154: IT | E154: East | F154: 45607 | G154: 46285 | H154: 15750000 | I154: 2010000 | J154: 16410000 | K154: 19201243 | L154: 17381460 | M154: 3532063.1 | N154: 3771824.6 | O154: Completed | P154: Medium

Sheet Investment_Master
A1: Investment Master & KPI Calculations
A2: Formula-driven master table | ApexNova Technologies Ltd.
A4: Investment_ID | B4: Investment_Name | C4: Investment_Category | D4: Department | E4: Region | F4: Start_Date | G4: End_Date | H4: Initial_Investment | I4: Additional_Investment | J4: Total_Investment | K4: Budgeted_Investment | L4: Expected_Revenue | M4: Actual_Revenue | N4: Expected_Cost_Savings | O4: Actual_Cost_Savings | P4: Expected_Return | Q4: Actual_Return | R4: Net_Benefit | S4: ROI_Pct | T4: Target_ROI_Pct | U4: ROI_Variance | V4: Payback_Years | W4: NPV | X4: IRR_Pct | Y4: Discount_Rate | Z4: Investment_Status | AA4: Risk_Level | AB4: Performance_Rating | AC4: Decision_Recommendation | AD4: Revenue_Achievement_Pct | AE4: Cost_Saving_Achievement_Pct | AF4: Investment_Variance | AG4: Performance_Score | AH4: ROI_Classification
A5: =Raw_Data!A5 -> INV-001 | B5: =Raw_Data!B5 -> ERP Cloud Migration – Central | C5: =Raw_Data!C5 -> Technology | D5: =Raw_Data!D5 -> HR | E5: =Raw_Data!E5 -> Central | F5: =Raw_Data!F5 -> 45925 | G5: =Raw_Data!G5 -> 46643 | H5: =Raw_Data!H5 -> 33630000 | I5: =Raw_Data!I5 -> 2620000 | J5: =H5+I5 -> 36250000 | K5: =Raw_Data!J5 -> 36270000 | L5: =Raw_Data!K5 -> 44295443 | M5: =Raw_Data!L5 -> 44650966 | N5: =Raw_Data!M5 -> 1555987.9 | O5: =Raw_Data!N5 -> 1252518.6 | P5: =L5+N5 -> 45851431 | Q5: =M5+O5 -> 45903484 | R5: =Q5-J5 -> 9653484.3 | S5: =IFERROR(R5/J5,0) -> 0.26630301 | T5: =IF(C5="Technology",0.2,IF(C5="Marketing",0.22,IF(C5="Product Development",0.24,IF(C5="Expansion",0.18,IF(C5="Equipment",0.17,IF(C5="Automation",0.25,IF(C5="Training",0.15,0.13))))))) -> 0.2 | U5: =S5-T5 -> 0.066303014 | V5: =IFERROR(J5/(Q5/5),0) -> 3.948502 | W5: =NPV(Y5,Q5/5,Q5/5,Q5/5,Q5/5,Q5/5)-J5 -> -2319089.9 | X5: =IFERROR(NPV_IRR!L5,0) -> 0.084238477 | Y5: =IF(D5="Finance",0.09,IF(G5-F5>600,0.11,IF(AA5="High",0.12,0.1))) -> 0.11 | Z5: =Raw_Data!O5 -> Active | AA5: =Raw_Data!P5 -> Low | AB5: =IF(AG5>=82,"Excellent",IF(AG5>=68,"Good",IF(AG5>=52,"Watch",IF(AG5>=35,"Underperforming","Critical")))) -> Watch | AC5: =IF(AND(AG5>=68,W5>0,AA5<>"High"),"Increase / Scale",IF(OR(AG5<35,W5<0),"Review / Restructure",IF(AND(AA5="High",U5>0),"Monitor Closely","Continue"))) -> Review / Restructure | AD5: =IFERROR(M5/L5,0) -> 1.0080262 | AE5: =IFERROR(O5/N5,0) -> 0.80496684 | AF5: =J5-K5 -> -20000 | AG5: =MAX(0,MIN(100,(MIN(100,MAX(0,50+U5*250))*22%)+(MIN(100,MAX(0,50+(W5/J5)*100))*18%)+(MIN(100,MAX(0,50+(X5-T5)*180))*15%)+(MIN(100,MAX(0,100-V5*12))*10%)+(MIN(100,MAX(0,100-MAX(0,AF5/K5)*250))*12%)+(MIN(100,MAX(0,AD5*100))*12%)+(MIN(100,MAX(0,AE5*100))*6%)+(IF(AA5="Low",100,IF(AA5="Medium",90,78))*5%))) -> 65.961155 | AH5: =IF(U5>=5%,"Significantly Above Target",IF(U5>=1.5%,"Above Target",IF(U5>=-1.5%,"On Target",IF(U5>=-5%,"Below Target","Significantly Below Target")))) -> Significantly Above Target
A6: =Raw_Data!A6 -> INV-002 | B6: =Raw_Data!B6 -> Brand Repositioning – South | C6: =Raw_Data!C6 -> Marketing | D6: =Raw_Data!D6 -> Supply Chain | E6: =Raw_Data!E6 -> South | F6: =Raw_Data!F6 -> 46045 | G6: =Raw_Data!G6 -> 46699 | H6: =Raw_Data!H6 -> 7490000 | I6: =Raw_Data!I6 -> 530000 | J6: =H6+I6 -> 8020000 | K6: =Raw_Data!J6 -> 8460000 | L6: =Raw_Data!K6 -> 9041768 | M6: =Raw_Data!L6 -> 9120793.5 | N6: =Raw_Data!M6 -> 356078.55 | O6: =Raw_Data!N6 -> 321968.96 | P6: =L6+N6 -> 9397846.6 | Q6: =M6+O6 -> 9442762.5 | R6: =Q6-J6 -> 1422762.5 | S6: =IFERROR(R6/J6,0) -> 0.17740181 | T6: =IF(C6="Technology",0.2,IF(C6="Marketing",0.22,IF(C6="Product Development",0.24,IF(C6="Expansion",0.18,IF(C6="Equipment",0.17,IF(C6="Automation",0.25,IF(C6="Training",0.15,0.13))))))) -> 0.22 | U6: =S6-T6 -> -0.042598195 | V6: =IFERROR(J6/(Q6/5),0) -> 4.2466386 | W6: =NPV(Y6,Q6/5,Q6/5,Q6/5,Q6/5,Q6/5)-J6 -> -1040104.5 | X6: =IFERROR(NPV_IRR!L6,0) -> 0.057028167 | Y6: =IF(D6="Finance",0.09,IF(G6-F6>600,0.11,IF(AA6="High",0.12,0.1))) -> 0.11 | Z6: =Raw_Data!O6 -> Completed | AA6: =Raw_Data!P6 -> High | AB6: =IF(AG6>=82,"Excellent",IF(AG6>=68,"Good",IF(AG6>=52,"Watch",IF(AG6>=35,"Underperforming","Critical")))) -> Watch | AC6: =IF(AND(AG6>=68,W6>0,AA6<>"High"),"Increase / Scale",IF(OR(AG6<35,W6<0),"Review / Restructure",IF(AND(AA6="High",U6>0),"Monitor Closely","Continue"))) -> Review / Restructure | AD6: =IFERROR(M6/L6,0) -> 1.00874 | AE6: =IFERROR(O6/N6,0) -> 0.90420769 | AF6: =J6-K6 -> -440000 | AG6: =MAX(0,MIN(100,(MIN(100,MAX(0,50+U6*250))*22%)+(MIN(100,MAX(0,50+(W6/J6)*100))*18%)+(MIN(100,MAX(0,50+(X6-T6)*180))*15%)+(MIN(100,MAX(0,100-V6*12))*10%)+(MIN(100,MAX(0,100-MAX(0,AF6/K6)*250))*12%)+(MIN(100,MAX(0,AD6*100))*12%)+(MIN(100,MAX(0,AE6*100))*6%)+(IF(AA6="Low",100,IF(AA6="Medium",90,78))*5%))) -> 56.65174 | AH6: =IF(U6>=5%,"Significantly Above Target",IF(U6>=1.5%,"Above Target",IF(U6>=-1.5%,"On Target",IF(U6>=-5%,"Below Target","Significantly Below Target")))) -> Below Target
A7: =Raw_Data!A7 -> INV-003 | B7: =Raw_Data!B7 -> Premium Product Line – West | C7: =Raw_Data!C7 -> Product Development | D7: =Raw_Data!D7 -> Operations | E7: =Raw_Data!E7 -> West | F7: =Raw_Data!F7 -> 45874 | G7: =Raw_Data!G7 -> 46411 | H7: =Raw_Data!H7 -> 34110000 | I7: =Raw_Data!I7 -> 1430000 | J7: =H7+I7 -> 35540000 | K7: =Raw_Data!J7 -> 36480000 | L7: =Raw_Data!K7 -> 40821273 | M7: =Raw_Data!L7 -> 38626369 | N7: =Raw_Data!M7 -> 3556096.6 | O7: =Raw_Data!N7 -> 3953686.5 | P7: =L7+N7 -> 44377370 | Q7: =M7+O7 -> 42580055 | R7: =Q7-J7 -> 7040055.1 | S7: =IFERROR(R7/J7,0) -> 0.19808821 | T7: =IF(C7="Technology",0.2,IF(C7="Marketing",0.22,IF(C7="Product Development",0.24,IF(C7="Expansion",0.18,IF(C7="Equipment",0.17,IF(C7="Automation",0.25,IF(C7="Training",0.15,0.13))))))) -> 0.24 | U7: =S7-T7 -> -0.041911786 | V7: =IFERROR(J7/(Q7/5),0) -> 4.1733154 | W7: =NPV(Y7,Q7/5,Q7/5,Q7/5,Q7/5,Q7/5)-J7 -> -3257618.1 | X7: =IFERROR(NPV_IRR!L7,0) -> 0.06343282 | Y7: =IF(D7="Finance",0.09,IF(G7-F7>600,0.11,IF(AA7="High",0.12,0.1))) -> 0.1 | Z7: =Raw_Data!O7 -> Cancelled | AA7: =Raw_Data!P7 -> Medium | AB7: =IF(AG7>=82,"Excellent",IF(AG7>=68,"Good",IF(AG7>=52,"Watch",IF(AG7>=35,"Underperforming","Critical")))) -> Watch | AC7: =IF(AND(AG7>=68,W7>0,AA7<>"High"),"Increase / Scale",IF(OR(AG7<35,W7<0),"Review / Restructure",IF(AND(AA7="High",U7>0),"Monitor Closely","Continue"))) -> Review / Restructure | AD7: =IFERROR(M7/L7,0) -> 0.94623135 | AE7: =IFERROR(O7/N7,0) -> 1.1118051 | AF7: =J7-K7 -> -940000 | AG7: =MAX(0,MIN(100,(MIN(100,MAX(0,50+U7*250))*22%)+(MIN(100,MAX(0,50+(W7/J7)*100))*18%)+(MIN(100,MAX(0,50+(X7-T7)*180))*15%)+(MIN(100,MAX(0,100-V7*12))*10%)+(MIN(100,MAX(0,100-MAX(0,AF7/K7)*250))*12%)+(MIN(100,MAX(0,AD7*100))*12%)+(MIN(100,MAX(0,AE7*100))*6%)+(IF(AA7="Low",100,IF(AA7="Medium",90,78))*5%))) -> 57.624445 | AH7: =IF(U7>=5%,"Significantly Above Target",IF(U7>=1.5%,"Above Target",IF(U7>=-1.5%,"On Target",IF(U7>=-5%,"Below Target","Significantly Below Target")))) -> Below Target
A8: =Raw_Data!A8 -> INV-004 | B8: =Raw_Data!B8 -> Tier-2 City Expansion – North | C8: =Raw_Data!C8 -> Expansion | D8: =Raw_Data!D8 -> Finance | E8: =Raw_Data!E8 -> North | F8: =Raw_Data!F8 -> 45405 | G8: =Raw_Data!G8 -> 45961 | H8: =Raw_Data!H8 -> 22460000 | I8: =Raw_Data!I8 -> 630000 | J8: =H8+I8 -> 23090000 | K8: =Raw_Data!J8 -> 24320000 | L8: =Raw_Data!K8 -> 26063425 | M8: =Raw_Data!L8 -> 25024555 | N8: =Raw_Data!M8 -> 2593160.2 | O8: =Raw_Data!N8 -> 2841181.8 | P8: =L8+N8 -> 28656585 | Q8: =M8+O8 -> 27865737 | R8: =Q8-J8 -> 4775736.8 | S8: =IFERROR(R8/J8,0) -> 0.20683139 | T8: =IF(C8="Technology",0.2,IF(C8="Marketing",0.22,IF(C8="Product Development",0.24,IF(C8="Expansion",0.18,IF(C8="Equipment",0.17,IF(C8="Automation",0.25,IF(C8="Training",0.15,0.13))))))) -> 0.18 | U8: =S8-T8 -> 0.026831392 | V8: =IFERROR(J8/(Q8/5),0) -> 4.1430808 | W8: =NPV(Y8,Q8/5,Q8/5,Q8/5,Q8/5,Q8/5)-J8 -> -1412400.3 | X8: =IFERROR(NPV_IRR!L8,0) -> 0.066126032 | Y8: =IF(D8="Finance",0.09,IF(G8-F8>600,0.11,IF(AA8="High",0.12,0.1))) -> 0.09 | Z8: =Raw_Data!O8 -> On Hold | AA8: =Raw_Data!P8 -> Low | AB8: =IF(AG8>=82,"Excellent",IF(AG8>=68,"Good",IF(AG8>=52,"Watch",IF(AG8>=35,"Underperforming","Critical")))) -> Watch | AC8: =IF(AND(AG8>=68,W8>0,AA8<>"High"),"Increase / Scale",IF(OR(AG8<35,W8<0),"Review / Restructure",IF(AND(AA8="High",U8>0),"Monitor Closely","Continue"))) -> Review / Restructure | AD8: =IFERROR(M8/L8,0) -> 0.96014069 | AE8: =IFERROR(O8/N8,0) -> 1.0956445 | AF8: =J8-K8 -> -1230000 | AG8: =MAX(0,MIN(100,(MIN(100,MAX(0,50+U8*250))*22%)+(MIN(100,MAX(0,50+(W8/J8)*100))*18%)+(MIN(100,MAX(0,50+(X8-T8)*180))*15%)+(MIN(100,MAX(0,100-V8*12))*10%)+(MIN(100,MAX(0,100-MAX(0,AF8/K8)*250))*12%)+(MIN(100,MAX(0,AD8*100))*12%)+(MIN(100,MAX(0,AE8*100))*6%)+(IF(AA8="Low",100,IF(AA8="Medium",90,78))*5%))) -> 64.350072 | AH8: =IF(U8>=5%,"Significantly Above Target",IF(U8>=1.5%,"Above Target",IF(U8>=-1.5%,"On Target",IF(U8>=-5%,"Below Target","Significantly Below Target")))) -> Above Target
A9: =Raw_Data!A9 -> INV-005 | B9: =Raw_Data!B9 -> Automated Packaging Line – East | C9: =Raw_Data!C9 -> Equipment | D9: =Raw_Data!D9 -> Sales | E9: =Raw_Data!E9 -> East | F9: =Raw_Data!F9 -> 45496 | G9: =Raw_Data!G9 -> 45852 | H9: =Raw_Data!H9 -> 27540000 | I9: =Raw_Data!I9 -> 3750000 | J9: =H9+I9 -> 31290000 | K9: =Raw_Data!J9 -> 30250000 | L9: =Raw_Data!K9 -> 33855626 | M9: =Raw_Data!L9 -> 34288710 | N9: =Raw_Data!M9 -> 2466361.7 | O9: =Raw_Data!N9 -> 2482722.1 | P9: =L9+N9 -> 36321988 | Q9: =M9+O9 -> 36771432 | R9: =Q9-J9 -> 5481431.7 | S9: =IFERROR(R9/J9,0) -> 0.17518158 | T9: =IF(C9="Technology",0.2,IF(C9="Marketing",0.22,IF(C9="Product Development",0.24,IF(C9="Expansion",0.18,IF(C9="Equipment",0.17,IF(C9="Automation",0.25,IF(C9="Training",0.15,0.13))))))) -> 0.17 | U9: =S9-T9 -> 0.0051815817 | V9: =IFERROR(J9/(Q9/5),0) -> 4.2546616 | W9: =NPV(Y9,Q9/5,Q9/5,Q9/5,Q9/5,Q9/5)-J9 -> -4779443.6 | X9: =IFERROR(NPV_IRR!L9,0) -> 0.056338011 | Y9: =IF(D9="Finance",0.09,IF(G9-F9>600,0.11,IF(AA9="High",0.12,0.1))) -> 0.12 | Z9: =Raw_Data!O9 -> Active | AA9: =Raw_Data!P9 -> High | AB9: =IF(AG9>=82,"Excellent",IF(AG9>=68,"Good",IF(AG9>=52,"Watch",IF(AG9>=35,"Underperforming","Critical")))) -> Watch | AC9: =IF(AND(AG9>=68,W9>0,AA9<>"High"),"Increase / Scale",IF(OR(AG9<35,W9<0),"Review / Restructure",IF(AND(AA9="High",U9>0),"Monitor Closely","Continue"))) -> Review / Restructure | AD9: =IFERROR(M9/L9,0) -> 1.0127921 | AE9: =IFERROR(O9/N9,0) -> 1.0066334 | AF9: =J9-K9 -> 1040000 | AG9: =MAX(0,MIN(100,(MIN(100,MAX(0,50+U9*250))*22%)+(MIN(100,MAX(0,50+(W9/J9)*100))*18%)+(MIN(100,MAX(0,50+(X9-T9)*180))*15%)+(MIN(100,MAX(0,100-V9*12))*10%)+(MIN(100,MAX(0,100-MAX(0,AF9/K9)*250))*12%)+(MIN(100,MAX(0,AD9*100))*12%)+(MIN(100,MAX(0,AE9*100))*6%)+(IF(AA9="Low",100,IF(AA9="Medium",90,78))*5%))) -> 59.729674 | AH9: =IF(U9>=5%,"Significantly Above Target",IF(U9>=1.5%,"Above Target",IF(U9>=-1.5%,"On Target",IF(U9>=-5%,"Below Target","Significantly Below Target")))) -> On Target
A10: =Raw_Data!A10 -> INV-006 | B10: =Raw_Data!B10 -> RPA Finance Rollout – Central | C10: =Raw_Data!C10 -> Automation | D10: =Raw_Data!D10 -> IT | E10: =Raw_Data!E10 -> Central | F10: =Raw_Data!F10 -> 45945 | G10: =Raw_Data!G10 -> 46142 | H10: =Raw_Data!H10 -> 17840000 | I10: =Raw_Data!I10 -> 1060000 | J10: =H10+I10 -> 18900000 | K10: =Raw_Data!J10 -> 17490000 | L10: =Raw_Data!K10 -> 21918904 | M10: =Raw_Data!L10 -> 21989015 | N10: =Raw_Data!M10 -> 1956666.5 | O10: =Raw_Data!N10 -> 1619526.8 | P10: =L10+N10 -> 23875571 | Q10: =M10+O10 -> 23608542 | R10: =Q10-J10 -> 4708542 | S10: =IFERROR(R10/J10,0) -> 0.24912921 | T10: =IF(C10="Technology",0.2,IF(C10="Marketing",0.22,IF(C10="Product Development",0.24,IF(C10="Expansion",0.18,IF(C10="Equipment",0.17,IF(C10="Automation",0.25,IF(C10="Training",0.15,0.13))))))) -> 0.25 | U10: =S10-T10 -> -0.00087079253 | V10: =IFERROR(J10/(Q10/5),0) -> 4.0027885 | W10: =NPV(Y10,Q10/5,Q10/5,Q10/5,Q10/5,Q10/5)-J10 -> -1001010.3 | X10: =IFERROR(NPV_IRR!L10,0) -> 0.079044196 | Y10: =IF(D10="Finance",0.09,IF(G10-F10>600,0.11,IF(AA10="High",0.12,0.1))) -> 0.1 | Z10: =Raw_Data!O10 -> Completed | AA10: =Raw_Data!P10 -> Medium | AB10: =IF(AG10>=82,"Excellent",IF(AG10>=68,"Good",IF(AG10>=52,"Watch",IF(AG10>=35,"Underperforming","Critical")))) -> Watch | AC10: =IF(AND(AG10>=68,W10>0,AA10<>"High"),"Increase / Scale",IF(OR(AG10<35,W10<0),"Review / Restructure",IF(AND(AA10="High",U10>0),"Monitor Closely","Continue"))) -> Review / Restructure | AD10: =IFERROR(M10/L10,0) -> 1.0031987 | AE10: =IFERROR(O10/N10,0) -> 0.8276969 | AF10: =J10-K10 -> 1410000 | AG10: =MAX(0,MIN(100,(MIN(100,MAX(0,50+U10*250))*22%)+(MIN(100,MAX(0,50+(W10/J10)*100))*18%)+(MIN(100,MAX(0,50+(X10-T10)*180))*15%)+(MIN(100,MAX(0,100-V10*12))*10%)+(MIN(100,MAX(0,100-MAX(0,AF10/K10)*250))*12%)+(MIN(100,MAX(0,AD10*100))*12%)+(MIN(100,MAX(0,AE10*100))*6%)+(IF(AA10="Low",100,IF(AA10="Medium",90,78))*5%))) -> 58.127267 | AH10: =IF(U10>=5%,"Significantly Above Target",IF(U10>=1.5%,"Above Target",IF(U10>=-1.5%,"On Target",IF(U10>=-5%,"Below Target","Significantly Below Target")))) -> On Target
A11: =Raw_Data!A11 -> INV-007 | B11: =Raw_Data!B11 -> Leadership Development – South | C11: =Raw_Data!C11 -> Training | D11: =Raw_Data!D11 -> Product | E11: =Raw_Data!E11 -> South | F11: =Raw_Data!F11 -> 46018 | G11: =Raw_Data!G11 -> 46874 | H11: =Raw_Data!H11 -> 11690000 | I11: =Raw_Data!I11 -> 1540000 | J11: =H11+I11 -> 13230000 | K11: =Raw_Data!J11 -> 12170000 | L11: =Raw_Data!K11 -> 13083912 | M11: =Raw_Data!L11 -> 11052861 | N11: =Raw_Data!M11 -> 2448716 | O11: =Raw_Data!N11 -> 2215229.6 | P11: =L11+N11 -> 15532628 | Q11: =M11+O11 -> 13268090 | R11: =Q11-J11 -> 38090.327 | S11: =IFERROR(R11/J11,0) -> 0.0028790875 | T11: =IF(C11="Technology",0.2,IF(C11="Marketing",0.22,IF(C11="Product Development",0.24,IF(C11="Expansion",0.18,IF(C11="Equipment",0.17,IF(C11="Automation",0.25,IF(C11="Training",0.15,0.13))))))) -> 0.15 | U11: =S11-T11 -> -0.14712091 | V11: =IFERROR(J11/(Q11/5),0) -> 4.9856459 | W11: =NPV(Y11,Q11/5,Q11/5,Q11/5,Q11/5,Q11/5)-J11 -> -3422500.9 | X11: =IFERROR(NPV_IRR!L11,0) -> 0.00095908289 | Y11: =IF(D11="Finance",0.09,IF(G11-F11>600,0.11,IF(AA11="High",0.12,0.1))) -> 0.11 | Z11: =Raw_Data!O11 -> Cancelled | AA11: =Raw_Data!P11 -> Low | AB11: =IF(AG11>=82,"Excellent",IF(AG11>=68,"Good",IF(AG11>=52,"Watch",IF(AG11>=35,"Underperforming","Critical")))) -> Underperforming | AC11: =IF(AND(AG11>=68,W11>0,AA11<>"High"),"Increase / Scale",IF(OR(AG11<35,W11<0),"Review / Restructure",IF(AND(AA11="High",U11>0),"Monitor Closely","Continue"))) -> Review / Restructure | AD11: =IFERROR(M11/L11,0) -> 0.84476729 | AE11: =IFERROR(O11/N11,0) -> 0.90464945 | AF11: =J11-K11 -> 1060000 | AG11: =MAX(0,MIN(100,(MIN(100,MAX(0,50+U11*250))*22%)+(MIN(100,MAX(0,50+(W11/J11)*100))*18%)+(MIN(100,MAX(0,50+(X11-T11)*180))*15%)+(MIN(100,MAX(0,100-V11*12))*10%)+(MIN(100,MAX(0,100-MAX(0,AF11/K11)*250))*12%)+(MIN(100,MAX(0,AD11*100))*12%)+(MIN(100,MAX(0,AE11*100))*6%)+(IF(AA11="Low",100,IF(AA11="Medium",90,78))*5%))) -> 44.697128 | AH11: =IF(U11>=5%,"Significantly Above Target",IF(U11>=1.5%,"Above Target",IF(U11>=-1.5%,"On Target",IF(U11>=-5%,"Below Target","Significantly Below Target")))) -> Significantly Below Target
A12: =Raw_Data!A12 -> INV-008 | B12: =Raw_Data!B12 -> Plant Utility Upgrade – West | C12: =Raw_Data!C12 -> Infrastructure | D12: =Raw_Data!D12 -> Marketing | E12: =Raw_Data!E12 -> West | F12: =Raw_Data!F12 -> 46029 | G12: =Raw_Data!G12 -> 46456 | H12: =Raw_Data!H12 -> 16360000 | I12: =Raw_Data!I12 -> 1260000 | J12: =H12+I12 -> 17620000 | K12: =Raw_Data!J12 -> 16370000 | L12: =Raw_Data!K12 -> 18270392 | M12: =Raw_Data!L12 -> 18724577 | N12: =Raw_Data!M12 -> 976615.75 | O12: =Raw_Data!N12 -> 913794.83 | P12: =L12+N12 -> 19247008 | Q12: =M12+O12 -> 19638372 | R12: =Q12-J12 -> 2018372.2 | S12: =IFERROR(R12/J12,0) -> 0.11455007 | T12: =IF(C12="Technology",0.2,IF(C12="Marketing",0.22,IF(C12="Product Development",0.24,IF(C12="Expansion",0.18,IF(C12="Equipment",0.17,IF(C12="Automation",0.25,IF(C12="Training",0.15,0.13))))))) -> 0.13 | U12: =S12-T12 -> -0.015449931 | V12: =IFERROR(J12/(Q12/5),0) -> 4.4861152 | W12: =NPV(Y12,Q12/5,Q12/5,Q12/5,Q12/5,Q12/5)-J12 -> -3461612.6 | X12: =IFERROR(NPV_IRR!L12,0) -> 0.037274472 | Y12: =IF(D12="Finance",0.09,IF(G12-F12>600,0.11,IF(AA12="High",0.12,0.1))) -> 0.12 | Z12: =Raw_Data!O12 -> On Hold | AA12: =Raw_Data!P12 -> High | AB12: =IF(AG12>=82,"Excellent",IF(AG12>=68,"Good",IF(AG12>=52,"Watch",IF(AG12>=35,"Underperforming","Critical")))) -> Watch | AC12: =IF(AND(AG12>=68,W12>0,AA12<>"High"),"Increase / Scale",IF(OR(AG12<35,W12<0),"Review / Restructure",IF(AND(AA12="High",U12>0),"Monitor Closely","Continue"))) -> Review / Restructure | AD12: =IFERROR(M12/L12,0) -> 1.0248591 | AE12: =IFERROR(O12/N12,0) -> 0.93567489 | AF12: =J12-K12 -> 1250000 | AG12: =MAX(0,MIN(100,(MIN(100,MAX(0,50+U12*250))*22%)+(MIN(100,MAX(0,50+(W12/J12)*100))*18%)+(MIN(100,MAX(0,50+(X12-T12)*180))*15%)+(MIN(100,MAX(0,100-V12*12))*10%)+(MIN(100,MAX(0,100-MAX(0,AF12/K12)*250))*12%)+(MIN(100,MAX(0,AD12*100))*12%)+(MIN(100,MAX(0,AE12*100))*6%)+(IF(AA12="Low",100,IF(AA12="Medium",90,78))*5%))) -> 56.450333 | AH12: =IF(U12>=5%,"Significantly Above Target",IF(U12>=1.5%,"Above Target",IF(U12>=-1.5%,"On Target",IF(U12>=-5%,"Below Target","Significantly Below Target")))) -> Below Target
A13: =Raw_Data!A13 -> INV-009 | B13: =Raw_Data!B13 -> ERP Cloud Migration – North | C13: =Raw_Data!C13 -> Technology | D13: =Raw_Data!D13 -> HR | E13: =Raw_Data!E13 -> North | F13: =Raw_Data!F13 -> 46028 | G13: =Raw_Data!G13 -> 46394 | H13: =Raw_Data!H13 -> 19340000 | I13: =Raw_Data!I13 -> 1500000 | J13: =H13+I13 -> 20840000 | K13: =Raw_Data!J13 -> 21430000 | L13: =Raw_Data!K13 -> 22689717 | M13: =Raw_Data!L13 -> 25582766 | N13: =Raw_Data!M13 -> 1907747.4 | O13: =Raw_Data!N13 -> 1520321.6 | P13: =L13+N13 -> 24597465 | Q13: =M13+O13 -> 27103088 | R13: =Q13-J13 -> 6263087.8 | S13: =IFERROR(R13/J13,0) -> 0.30053205 | T13: =IF(C13="Technology",0.2,IF(C13="Marketing",0.22,IF(C13="Product Development",0.24,IF(C13="Expansion",0.18,IF(C13="Equipment",0.17,IF(C13="Automation",0.25,IF(C13="Training",0.15,0.13))))))) -> 0.2 | U13: =S13-T13 -> 0.10053205 | V13: =IFERROR(J13/(Q13/5),0) -> 3.8445804 | W13: =NPV(Y13,Q13/5,Q13/5,Q13/5,Q13/5,Q13/5)-J13 -> -291594.64 | X13: =IFERROR(NPV_IRR!L13,0) -> 0.0945077 | Y13: =IF(D13="Finance",0.09,IF(G13-F13>600,0.11,IF(AA13="High",0.12,0.1))) -> 0.1 | Z13: =Raw_Data!O13 -> Active | AA13: =Raw_Data!P13 -> Medium | AB13: =IF(AG13>=82,"Excellent",IF(AG13>=68,"Good",IF(AG13>=52,"Watch",IF(AG13>=35,"Underperforming","Critical")))) -> Good | AC13: =IF(AND(AG13>=68,W13>0,AA13<>"High"),"Increase / Scale",IF(OR(AG13<35,W13<0),"Review / Restructure",IF(AND(AA13="High",U13>0),"Monitor Closely","Continue"))) -> Review / Restructure | AD13: =IFERROR(M13/L13,0) -> 1.1275049 | AE13: =IFERROR(O13/N13,0) -> 0.79691979 | AF13: =J13-K13 -> -590000 | AG13: =MAX(0,MIN(100,(MIN(100,MAX(0,50+U13*250))*22%)+(MIN(100,MAX(0,50+(W13/J13)*100))*18%)+(MIN(100,MAX(0,50+(X13-T13)*180))*15%)+(MIN(100,MAX(0,100-V13*12))*10%)+(MIN(100,MAX(0,100-MAX(0,AF13/K13)*250))*12%)+(MIN(100,MAX(0,AD13*100))*12%)+(MIN(100,MAX(0,AE13*100))*6%)+(IF(AA13="Low",100,IF(AA13="Medium",90,78))*5%))) -> 68.597136 | AH13: =IF(U13>=5%,"Significantly Above Target",IF(U13>=1.5%,"Above Target",IF(U13>=-1.5%,"On Target",IF(U13>=-5%,"Below Target","Significantly Below Target")))) -> Significantly Above Target
A14: =Raw_Data!A14 -> INV-010 | B14: =Raw_Data!B14 -> Brand Repositioning – East | C14: =Raw_Data!C14 -> Marketing | D14: =Raw_Data!D14 -> Supply Chain | E14: =Raw_Data!E14 -> East | F14: =Raw_Data!F14 -> 45619 | G14: =Raw_Data!G14 -> 45899 | H14: =Raw_Data!H14 -> 9210000 | I14: =Raw_Data!I14 -> 300000 | J14: =H14+I14 -> 9510000 | K14: =Raw_Data!J14 -> 9850000 | L14: =Raw_Data!K14 -> 10046184 | M14: =Raw_Data!L14 -> 10085255 | N14: =Raw_Data!M14 -> 1515144.5 | O14: =Raw_Data!N14 -> 1663386.1 | P14: =L14+N14 -> 11561329 | Q14: =M14+O14 -> 11748641 | R14: =Q14-J14 -> 2238641.4 | S14: =IFERROR(R14/J14,0) -> 0.23539867 | T14: =IF(C14="Technology",0.2,IF(C14="Marketing",0.22,IF(C14="Product Development",0.24,IF(C14="Expansion",0.18,IF(C14="Equipment",0.17,IF(C14="Automation",0.25,IF(C14="Training",0.15,0.13))))))) -> 0.22 | U14: =S14-T14 -> 0.015398672 | V14: =IFERROR(J14/(Q14/5),0) -> 4.0472765 | W14: =NPV(Y14,Q14/5,Q14/5,Q14/5,Q14/5,Q14/5)-J14 -> -602681.15 | X14: =IFERROR(NPV_IRR!L14,0) -> 0.074870558 | Y14: =IF(D14="Finance",0.09,IF(G14-F14>600,0.11,IF(AA14="High",0.12,0.1))) -> 0.1 | Z14: =Raw_Data!O14 -> Completed | AA14: =Raw_Data!P14 -> Low | AB14: =IF(AG14>=82,"Excellent",IF(AG14>=68,"Good",IF(AG14>=52,"Watch",IF(AG14>=35,"Underperforming","Critical")))) -> Watch | AC14: =IF(AND(AG14>=68,W14>0,AA14<>"High"),"Increase / Scale",IF(OR(AG14<35,W14<0),"Review / Restructure",IF(AND(AA14="High",U14>0),"Monitor Closely","Continue"))) -> Review / Restructure | AD14: =IFERROR(M14/L14,0) -> 1.0038891 | AE14: =IFERROR(O14/N14,0) -> 1.0978399 | AF14: =J14-K14 -> -340000 | AG14: =MAX(0,MIN(100,(MIN(100,MAX(0,50+U14*250))*22%)+(MIN(100,MAX(0,50+(W14/J14)*100))*18%)+(MIN(100,MAX(0,50+(X14-T14)*180))*15%)+(MIN(100,MAX(0,100-V14*12))*10%)+(MIN(100,MAX(0,100-MAX(0,AF14/K14)*250))*12%)+(MIN(100,MAX(0,AD14*100))*12%)+(MIN(100,MAX(0,AE14*100))*6%)+(IF(AA14="Low",100,IF(AA14="Medium",90,78))*5%))) -> 63.430979 | AH14: =IF(U14>=5%,"Significantly Above Target",IF(U14>=1.5%,"Above Target",IF(U14>=-1.5%,"On Target",IF(U14>=-5%,"Below Target","Significantly Below Target")))) -> Above Target
A15: =Raw_Data!A15 -> INV-011 | B15: =Raw_Data!B15 -> Premium Product Line – Central | C15: =Raw_Data!C15 -> Product Development | D15: =Raw_Data!D15 -> Operations | E15: =Raw_Data!E15 -> Central | F15: =Raw_Data!F15 -> 45509 | G15: =Raw_Data!G15 -> 45881 | H15: =Raw_Data!H15 -> 20670000 | I15: =Raw_Data!I15 -> 3360000 | J15: =H15+I15 -> 24030000 | K15: =Raw_Data!J15 -> 25610000 | L15: =Raw_Data!K15 -> 25230103 | M15: =Raw_Data!L15 -> 21668941 | N15: =Raw_Data!M15 -> 3686889.1 | O15: =Raw_Data!N15 -> 3871983.4 | P15: =L15+N15 -> 28916992 | Q15: =M15+O15 -> 25540924 | R15: =Q15-J15 -> 1510924.3 | S15: =IFERROR(R15/J15,0) -> 0.062876582 | T15: =IF(C15="Technology",0.2,IF(C15="Marketing",0.22,IF(C15="Product Development",0.24,IF(C15="Expansion",0.18,IF(C15="Equipment",0.17,IF(C15="Automation",0.25,IF(C15="Training",0.15,0.13))))))) -> 0.24 | U15: =S15-T15 -> -0.17712342 | V15: =IFERROR(J15/(Q15/5),0) -> 4.704215 | W15: =NPV(Y15,Q15/5,Q15/5,Q15/5,Q15/5,Q15/5)-J15 -> -5616136.8 | X15: =IFERROR(NPV_IRR!L15,0) -> 0.020676798 | Y15: =IF(D15="Finance",0.09,IF(G15-F15>600,0.11,IF(AA15="High",0.12,0.1))) -> 0.12 | Z15: =Raw_Data!O15 -> Cancelled | AA15: =Raw_Data!P15 -> High | AB15: =IF(AG15>=82,"Excellent",IF(AG15>=68,"Good",IF(AG15>=52,"Watch",IF(AG15>=35,"Underperforming","Critical")))) -> Underperforming | AC15: =IF(AND(AG15>=68,W15>0,AA15<>"High"),"Increase / Scale",IF(OR(AG15<35,W15<0),"Review / Restructure",IF(AND(AA15="High",U15>0),"Monitor Closely","Continue"))) -> Review / Restructure | AD15: =IFERROR(M15/L15,0) -> 0.85885266 | AE15: =IFERROR(O15/N15,0) -> 1.0502034 | AF15: =J15-K15 -> -1580000 | AG15: =MAX(0,MIN(100,(MIN(100,MAX(0,50+U15*250))*22%)+(MIN(100,MAX(0,50+(W15/J15)*100))*18%)+(MIN(100,MAX(0,50+(X15-T15)*180))*15%)+(MIN(100,MAX(0,100-V15*12))*10%)+(MIN(100,MAX(0,100-MAX(0,AF15/K15)*250))*12%)+(MIN(100,MAX(0,AD15*100))*12%)+(MIN(100,MAX(0,AE15*100))*6%)+(IF(AA15="Low",100,IF(AA15="Medium",90,78))*5%))) -> 44.190815 | AH15: =IF(U15>=5%,"Significantly Above Target",IF(U15>=1.5%,"Above Target",IF(U15>=-1.5%,"On Target",IF(U15>=-5%,"Below Target","Significantly Below Target")))) -> Significantly Below Target
A16: =Raw_Data!A16 -> INV-012 | B16: =Raw_Data!B16 -> Tier-2 City Expansion – South | C16: =Raw_Data!C16 -> Expansion | D16: =Raw_Data!D16 -> Finance | E16: =Raw_Data!E16 -> South | F16: =Raw_Data!F16 -> 45969 | G16: =Raw_Data!G16 -> 46674 | H16: =Raw_Data!H16 -> 26920000 | I16: =Raw_Data!I16 -> 2850000 | J16: =H16+I16 -> 29770000 | K16: =Raw_Data!J16 -> 30060000 | L16: =Raw_Data!K16 -> 29157879 | M16: =Raw_Data!L16 -> 30935879 | N16: =Raw_Data!M16 -> 5375701 | O16: =Raw_Data!N16 -> 4111287.5 | P16: =L16+N16 -> 34533580 | Q16: =M16+O16 -> 35047167 | R16: =Q16-J16 -> 5277166.7 | S16: =IFERROR(R16/J16,0) -> 0.17726458 | T16: =IF(C16="Technology",0.2,IF(C16="Marketing",0.22,IF(C16="Product Development",0.24,IF(C16="Expansion",0.18,IF(C16="Equipment",0.17,IF(C16="Automation",0.25,IF(C16="Training",0.15,0.13))))))) -> 0.18 | U16: =S16-T16 -> -0.0027354161 | V16: =IFERROR(J16/(Q16/5),0) -> 4.2471336 | W16: =NPV(Y16,Q16/5,Q16/5,Q16/5,Q16/5,Q16/5)-J16 -> -2505748.8 | X16: =IFERROR(NPV_IRR!L16,0) -> 0.056985528 | Y16: =IF(D16="Finance",0.09,IF(G16-F16>600,0.11,IF(AA16="High",0.12,0.1))) -> 0.09 | Z16: =Raw_Data!O16 -> On Hold | AA16: =Raw_Data!P16 -> Medium | AB16: =IF(AG16>=82,"Excellent",IF(AG16>=68,"Good",IF(AG16>=52,"Watch",IF(AG16>=35,"Underperforming","Critical")))) -> Watch | AC16: =IF(AND(AG16>=68,W16>0,AA16<>"High"),"Increase / Scale",IF(OR(AG16<35,W16<0),"Review / Restructure",IF(AND(AA16="High",U16>0),"Monitor Closely","Continue"))) -> Review / Restructure | AD16: =IFERROR(M16/L16,0) -> 1.0609784 | AE16: =IFERROR(O16/N16,0) -> 0.76479095 | AF16: =J16-K16 -> -290000 | AG16: =MAX(0,MIN(100,(MIN(100,MAX(0,50+U16*250))*22%)+(MIN(100,MAX(0,50+(W16/J16)*100))*18%)+(MIN(100,MAX(0,50+(X16-T16)*180))*15%)+(MIN(100,MAX(0,100-V16*12))*10%)+(MIN(100,MAX(0,100-MAX(0,AF16/K16)*250))*12%)+(MIN(100,MAX(0,AD16*100))*12%)+(MIN(100,MAX(0,AE16*100))*6%)+(IF(AA16="Low",100,IF(AA16="Medium",90,78))*5%))) -> 60.505282 | AH16: =IF(U16>=5%,"Significantly Above Target",IF(U16>=1.5%,"Above Target",IF(U16>=-1.5%,"On Target",IF(U16>=-5%,"Below Target","Significantly Below Target")))) -> On Target
... A154: =Raw_Data!A154 -> INV-150 | B154: =Raw_Data!B154 -> RPA Finance Rollout – East | C154: =Raw_Data!C154 -> Automation | D154: =Raw_Data!D154 -> IT | E154: =Raw_Data!E154 -> East | F154: =Raw_Data!F154 -> 45607 | G154: =Raw_Data!G154 -> 46285 | H154: =Raw_Data!H154 -> 15750000 | I154: =Raw_Data!I154 -> 2010000 | J154: =H154+I154 -> 17760000 | K154: =Raw_Data!J154 -> 16410000 | L154: =Raw_Data!K154 -> 19201243 | M154: =Raw_Data!L154 -> 17381460 | N154: =Raw_Data!M154 -> 3532063.1 | O154: =Raw_Data!N154 -> 3771824.6 | P154: =L154+N154 -> 22733306 | Q154: =M154+O154 -> 21153285 | R154: =Q154-J154 -> 3393284.9 | S154: =IFERROR(R154/J154,0) -> 0.19106334 | T154: =IF(C154="Technology",0.2,IF(C154="Marketing",0.22,IF(C154="Product Development",0.24,IF(C154="Expansion",0.18,IF(C154="Equipment",0.17,IF(C154="Automation",0.25,IF(C154="Training",0.15,0.13))))))) -> 0.25 | U154: =S154-T154 -> -0.05893666 | V154: =IFERROR(J154/(Q154/5),0) -> 4.1979296 | W154: =NPV(Y154,Q154/5,Q154/5,Q154/5,Q154/5,Q154/5)-J154 -> -2123927.5 | X154: =IFERROR(NPV_IRR!L154,0) -> 0.061263036 | Y154: =IF(D154="Finance",0.09,IF(G154-F154>600,0.11,IF(AA154="High",0.12,0.1))) -> 0.11 | Z154: =Raw_Data!O154 -> Completed | AA154: =Raw_Data!P154 -> Medium | AB154: =IF(AG154>=82,"Excellent",IF(AG154>=68,"Good",IF(AG154>=52,"Watch",IF(AG154>=35,"Underperforming","Critical")))) -> Watch | AC154: =IF(AND(AG154>=68,W154>0,AA154<>"High"),"Increase / Scale",IF(OR(AG154<35,W154<0),"Review / Restructure",IF(AND(AA154="High",U154>0),"Monitor Closely","Continue"))) -> Review / Restructure | AD154: =IFERROR(M154/L154,0) -> 0.90522581 | AE154: =IFERROR(O154/N154,0) -> 1.0678814 | AF154: =J154-K154 -> 1350000 | AG154: =MAX(0,MIN(100,(MIN(100,MAX(0,50+U154*250))*22%)+(MIN(100,MAX(0,50+(W154/J154)*100))*18%)+(MIN(100,MAX(0,50+(X154-T154)*180))*15%)+(MIN(100,MAX(0,100-V154*12))*10%)+(MIN(100,MAX(0,100-MAX(0,AF154/K154)*250))*12%)+(MIN(100,MAX(0,AD154*100))*12%)+(MIN(100,MAX(0,AE154*100))*6%)+(IF(AA154="Low",100,IF(AA154="Medium",90,78))*5%))) -> 52.867143 | AH154: =IF(U154>=5%,"Significantly Above Target",IF(U154>=1.5%,"Above Target",IF(U154>=-1.5%,"On Target",IF(U154>=-5%,"Below Target","Significantly Below Target")))) -> Significantly Below Target

Sheet ROI_Analysis
A1: ROI & Target Variance Analysis
A2: Actual ROI vs target ROI with management classification
A4: Investment_ID | B4: Investment_Name | C4: Category | D4: Department | E4: Total Investment | F4: Actual ROI | G4: Target ROI | H4: ROI Variance | I4: ROI Classification | J4: Performance Rating | K4: Recommendation
A5: =Investment_Master!A5 -> INV-001 | B5: =Investment_Master!B5 -> ERP Cloud Migration – Central | C5: =Investment_Master!C5 -> Technology | D5: =Investment_Master!D5 -> HR | E5: =Investment_Master!J5 -> 36250000 | F5: =Investment_Master!S5 -> 0.26630301 | G5: =Investment_Master!T5 -> 0.2 | H5: =Investment_Master!U5 -> 0.066303014 | I5: =Investment_Master!AH5 -> Significantly Above Target | J5: =Investment_Master!AB5 -> Watch | K5: =Investment_Master!AC5 -> Review / Restructure
A6: =Investment_Master!A6 -> INV-002 | B6: =Investment_Master!B6 -> Brand Repositioning – South | C6: =Investment_Master!C6 -> Marketing | D6: =Investment_Master!D6 -> Supply Chain | E6: =Investment_Master!J6 -> 8020000 | F6: =Investment_Master!S6 -> 0.17740181 | G6: =Investment_Master!T6 -> 0.22 | H6: =Investment_Master!U6 -> -0.042598195 | I6: =Investment_Master!AH6 -> Below Target | J6: =Investment_Master!AB6 -> Watch | K6: =Investment_Master!AC6 -> Review / Restructure
A7: =Investment_Master!A7 -> INV-003 | B7: =Investment_Master!B7 -> Premium Product Line – West | C7: =Investment_Master!C7 -> Product Development | D7: =Investment_Master!D7 -> Operations | E7: =Investment_Master!J7 -> 35540000 | F7: =Investment_Master!S7 -> 0.19808821 | G7: =Investment_Master!T7 -> 0.24 | H7: =Investment_Master!U7 -> -0.041911786 | I7: =Investment_Master!AH7 -> Below Target | J7: =Investment_Master!AB7 -> Watch | K7: =Investment_Master!AC7 -> Review / Restructure
A8: =Investment_Master!A8 -> INV-004 | B8: =Investment_Master!B8 -> Tier-2 City Expansion – North | C8: =Investment_Master!C8 -> Expansion | D8: =Investment_Master!D8 -> Finance | E8: =Investment_Master!J8 -> 23090000 | F8: =Investment_Master!S8 -> 0.20683139 | G8: =Investment_Master!T8 -> 0.18 | H8: =Investment_Master!U8 -> 0.026831392 | I8: =Investment_Master!AH8 -> Above Target | J8: =Investment_Master!AB8 -> Watch | K8: =Investment_Master!AC8 -> Review / Restructure
A9: =Investment_Master!A9 -> INV-005 | B9: =Investment_Master!B9 -> Automated Packaging Line – East | C9: =Investment_Master!C9 -> Equipment | D9: =Investment_Master!D9 -> Sales | E9: =Investment_Master!J9 -> 31290000 | F9: =Investment_Master!S9 -> 0.17518158 | G9: =Investment_Master!T9 -> 0.17 | H9: =Investment_Master!U9 -> 0.0051815817 | I9: =Investment_Master!AH9 -> On Target | J9: =Investment_Master!AB9 -> Watch | K9: =Investment_Master!AC9 -> Review / Restructure
A10: =Investment_Master!A10 -> INV-006 | B10: =Investment_Master!B10 -> RPA Finance Rollout – Central | C10: =Investment_Master!C10 -> Automation | D10: =Investment_Master!D10 -> IT | E10: =Investment_Master!J10 -> 18900000 | F10: =Investment_Master!S10 -> 0.24912921 | G10: =Investment_Master!T10 -> 0.25 | H10: =Investment_Master!U10 -> -0.00087079253 | I10: =Investment_Master!AH10 -> On Target | J10: =Investment_Master!AB10 -> Watch | K10: =Investment_Master!AC10 -> Review / Restructure
A11: =Investment_Master!A11 -> INV-007 | B11: =Investment_Master!B11 -> Leadership Development – South | C11: =Investment_Master!C11 -> Training | D11: =Investment_Master!D11 -> Product | E11: =Investment_Master!J11 -> 13230000 | F11: =Investment_Master!S11 -> 0.0028790875 | G11: =Investment_Master!T11 -> 0.15 | H11: =Investment_Master!U11 -> -0.14712091 | I11: =Investment_Master!AH11 -> Significantly Below Target | J11: =Investment_Master!AB11 -> Underperforming | K11: =Investment_Master!AC11 -> Review / Restructure
A12: =Investment_Master!A12 -> INV-008 | B12: =Investment_Master!B12 -> Plant Utility Upgrade – West | C12: =Investment_Master!C12 -> Infrastructure | D12: =Investment_Master!D12 -> Marketing | E12: =Investment_Master!J12 -> 17620000 | F12: =Investment_Master!S12 -> 0.11455007 | G12: =Investment_Master!T12 -> 0.13 | H12: =Investment_Master!U12 -> -0.015449931 | I12: =Investment_Master!AH12 -> Below Target | J12: =Investment_Master!AB12 -> Watch | K12: =Investment_Master!AC12 -> Review / Restructure
A13: =Investment_Master!A13 -> INV-009 | B13: =Investment_Master!B13 -> ERP Cloud Migration – North | C13: =Investment_Master!C13 -> Technology | D13: =Investment_Master!D13 -> HR | E13: =Investment_Master!J13 -> 20840000 | F13: =Investment_Master!S13 -> 0.30053205 | G13: =Investment_Master!T13 -> 0.2 | H13: =Investment_Master!U13 -> 0.10053205 | I13: =Investment_Master!AH13 -> Significantly Above Target | J13: =Investment_Master!AB13 -> Good | K13: =Investment_Master!AC13 -> Review / Restructure
A14: =Investment_Master!A14 -> INV-010 | B14: =Investment_Master!B14 -> Brand Repositioning – East | C14: =Investment_Master!C14 -> Marketing | D14: =Investment_Master!D14 -> Supply Chain | E14: =Investment_Master!J14 -> 9510000 | F14: =Investment_Master!S14 -> 0.23539867 | G14: =Investment_Master!T14 -> 0.22 | H14: =Investment_Master!U14 -> 0.015398672 | I14: =Investment_Master!AH14 -> Above Target | J14: =Investment_Master!AB14 -> Watch | K14: =Investment_Master!AC14 -> Review / Restructure
A15: =Investment_Master!A15 -> INV-011 | B15: =Investment_Master!B15 -> Premium Product Line – Central | C15: =Investment_Master!C15 -> Product Development | D15: =Investment_Master!D15 -> Operations | E15: =Investment_Master!J15 -> 24030000 | F15: =Investment_Master!S15 -> 0.062876582 | G15: =Investment_Master!T15 -> 0.24 | H15: =Investment_Master!U15 -> -0.17712342 | I15: =Investment_Master!AH15 -> Significantly Below Target | J15: =Investment_Master!AB15 -> Underperforming | K15: =Investment_Master!AC15 -> Review / Restructure
A16: =Investment_Master!A16 -> INV-012 | B16: =Investment_Master!B16 -> Tier-2 City Expansion – South | C16: =Investment_Master!C16 -> Expansion | D16: =Investment_Master!D16 -> Finance | E16: =Investment_Master!J16 -> 29770000 | F16: =Investment_Master!S16 -> 0.17726458 | G16: =Investment_Master!T16 -> 0.18 | H16: =Investment_Master!U16 -> -0.0027354161 | I16: =Investment_Master!AH16 -> On Target | J16: =Investment_Master!AB16 -> Watch | K16: =Investment_Master!AC16 -> Review / Restructure
... A154: =Investment_Master!A154 -> INV-150 | B154: =Investment_Master!B154 -> RPA Finance Rollout – East | C154: =Investment_Master!C154 -> Automation | D154: =Investment_Master!D154 -> IT | E154: =Investment_Master!J154 -> 17760000 | F154: =Investment_Master!S154 -> 0.19106334 | G154: =Investment_Master!T154 -> 0.25 | H154: =Investment_Master!U154 -> -0.05893666 | I154: =Investment_Master!AH154 -> Significantly Below Target | J154: =Investment_Master!AB154 -> Watch | K154: =Investment_Master!AC154 -> Review / Restructure

Sheet NPV_IRR
A1: NPV, IRR & Cash Flow Analysis
A2: Five-year illustrative cash-flow schedule for investment evaluation
A4: Investment_ID | B4: Investment_Name | C4: Initial Investment | D4: Discount Rate | E4: Year 0 | F4: Year 1 | G4: Year 2 | H4: Year 3 | I4: Year 4 | J4: Year 5 | K4: NPV | L4: IRR | M4: Payback Years
A5: =Investment_Master!A5 -> INV-001 | B5: =Investment_Master!B5 -> ERP Cloud Migration – Central | C5: =Investment_Master!J5 -> 36250000 | D5: =Investment_Master!Y5 -> 0.11 | E5: =-C5 -> -36250000 | F5: =Investment_Master!Q5/5 -> 9180696.9 | G5: =Investment_Master!Q5/5 -> 9180696.9 | H5: =Investment_Master!Q5/5 -> 9180696.9 | I5: =Investment_Master!Q5/5 -> 9180696.9 | J5: =Investment_Master!Q5/5 -> 9180696.9 | K5: =NPV(D5,F5:J5)+E5 -> -2319089.9 | L5: =IFERROR(IRR(E5:J5),0) -> 0.084238477 | M5: =Investment_Master!V5 -> 3.948502
A6: =Investment_Master!A6 -> INV-002 | B6: =Investment_Master!B6 -> Brand Repositioning – South | C6: =Investment_Master!J6 -> 8020000 | D6: =Investment_Master!Y6 -> 0.11 | E6: =-C6 -> -8020000 | F6: =Investment_Master!Q6/5 -> 1888552.5 | G6: =Investment_Master!Q6/5 -> 1888552.5 | H6: =Investment_Master!Q6/5 -> 1888552.5 | I6: =Investment_Master!Q6/5 -> 1888552.5 | J6: =Investment_Master!Q6/5 -> 1888552.5 | K6: =NPV(D6,F6:J6)+E6 -> -1040104.5 | L6: =IFERROR(IRR(E6:J6),0) -> 0.057028167 | M6: =Investment_Master!V6 -> 4.2466386
A7: =Investment_Master!A7 -> INV-003 | B7: =Investment_Master!B7 -> Premium Product Line – West | C7: =Investment_Master!J7 -> 35540000 | D7: =Investment_Master!Y7 -> 0.1 | E7: =-C7 -> -35540000 | F7: =Investment_Master!Q7/5 -> 8516011 | G7: =Investment_Master!Q7/5 -> 8516011 | H7: =Investment_Master!Q7/5 -> 8516011 | I7: =Investment_Master!Q7/5 -> 8516011 | J7: =Investment_Master!Q7/5 -> 8516011 | K7: =NPV(D7,F7:J7)+E7 -> -3257618.1 | L7: =IFERROR(IRR(E7:J7),0) -> 0.06343282 | M7: =Investment_Master!V7 -> 4.1733154
A8: =Investment_Master!A8 -> INV-004 | B8: =Investment_Master!B8 -> Tier-2 City Expansion – North | C8: =Investment_Master!J8 -> 23090000 | D8: =Investment_Master!Y8 -> 0.09 | E8: =-C8 -> -23090000 | F8: =Investment_Master!Q8/5 -> 5573147.4 | G8: =Investment_Master!Q8/5 -> 5573147.4 | H8: =Investment_Master!Q8/5 -> 5573147.4 | I8: =Investment_Master!Q8/5 -> 5573147.4 | J8: =Investment_Master!Q8/5 -> 5573147.4 | K8: =NPV(D8,F8:J8)+E8 -> -1412400.3 | L8: =IFERROR(IRR(E8:J8),0) -> 0.066126032 | M8: =Investment_Master!V8 -> 4.1430808
A9: =Investment_Master!A9 -> INV-005 | B9: =Investment_Master!B9 -> Automated Packaging Line – East | C9: =Investment_Master!J9 -> 31290000 | D9: =Investment_Master!Y9 -> 0.12 | E9: =-C9 -> -31290000 | F9: =Investment_Master!Q9/5 -> 7354286.3 | G9: =Investment_Master!Q9/5 -> 7354286.3 | H9: =Investment_Master!Q9/5 -> 7354286.3 | I9: =Investment_Master!Q9/5 -> 7354286.3 | J9: =Investment_Master!Q9/5 -> 7354286.3 | K9: =NPV(D9,F9:J9)+E9 -> -4779443.6 | L9: =IFERROR(IRR(E9:J9),0) -> 0.056338011 | M9: =Investment_Master!V9 -> 4.2546616
A10: =Investment_Master!A10 -> INV-006 | B10: =Investment_Master!B10 -> RPA Finance Rollout – Central | C10: =Investment_Master!J10 -> 18900000 | D10: =Investment_Master!Y10 -> 0.1 | E10: =-C10 -> -18900000 | F10: =Investment_Master!Q10/5 -> 4721708.4 | G10: =Investment_Master!Q10/5 -> 4721708.4 | H10: =Investment_Master!Q10/5 -> 4721708.4 | I10: =Investment_Master!Q10/5 -> 4721708.4 | J10: =Investment_Master!Q10/5 -> 4721708.4 | K10: =NPV(D10,F10:J10)+E10 -> -1001010.3 | L10: =IFERROR(IRR(E10:J10),0) -> 0.079044196 | M10: =Investment_Master!V10 -> 4.0027885
A11: =Investment_Master!A11 -> INV-007 | B11: =Investment_Master!B11 -> Leadership Development – South | C11: =Investment_Master!J11 -> 13230000 | D11: =Investment_Master!Y11 -> 0.11 | E11: =-C11 -> -13230000 | F11: =Investment_Master!Q11/5 -> 2653618.1 | G11: =Investment_Master!Q11/5 -> 2653618.1 | H11: =Investment_Master!Q11/5 -> 2653618.1 | I11: =Investment_Master!Q11/5 -> 2653618.1 | J11: =Investment_Master!Q11/5 -> 2653618.1 | K11: =NPV(D11,F11:J11)+E11 -> -3422500.9 | L11: =IFERROR(IRR(E11:J11),0) -> 0.00095908289 | M11: =Investment_Master!V11 -> 4.9856459
A12: =Investment_Master!A12 -> INV-008 | B12: =Investment_Master!B12 -> Plant Utility Upgrade – West | C12: =Investment_Master!J12 -> 17620000 | D12: =Investment_Master!Y12 -> 0.12 | E12: =-C12 -> -17620000 | F12: =Investment_Master!Q12/5 -> 3927674.4 | G12: =Investment_Master!Q12/5 -> 3927674.4 | H12: =Investment_Master!Q12/5 -> 3927674.4 | I12: =Investment_Master!Q12/5 -> 3927674.4 | J12: =Investment_Master!Q12/5 -> 3927674.4 | K12: =NPV(D12,F12:J12)+E12 -> -3461612.6 | L12: =IFERROR(IRR(E12:J12),0) -> 0.037274472 | M12: =Investment_Master!V12 -> 4.4861152
A13: =Investment_Master!A13 -> INV-009 | B13: =Investment_Master!B13 -> ERP Cloud Migration – North | C13: =Investment_Master!J13 -> 20840000 | D13: =Investment_Master!Y13 -> 0.1 | E13: =-C13 -> -20840000 | F13: =Investment_Master!Q13/5 -> 5420617.6 | G13: =Investment_Master!Q13/5 -> 5420617.6 | H13: =Investment_Master!Q13/5 -> 5420617.6 | I13: =Investment_Master!Q13/5 -> 5420617.6 | J13: =Investment_Master!Q13/5 -> 5420617.6 | K13: =NPV(D13,F13:J13)+E13 -> -291594.64 | L13: =IFERROR(IRR(E13:J13),0) -> 0.0945077 | M13: =Investment_Master!V13 -> 3.8445804
A14: =Investment_Master!A14 -> INV-010 | B14: =Investment_Master!B14 -> Brand Repositioning – East | C14: =Investment_Master!J14 -> 9510000 | D14: =Investment_Master!Y14 -> 0.1 | E14: =-C14 -> -9510000 | F14: =Investment_Master!Q14/5 -> 2349728.3 | G14: =Investment_Master!Q14/5 -> 2349728.3 | H14: =Investment_Master!Q14/5 -> 2349728.3 | I14: =Investment_Master!Q14/5 -> 2349728.3 | J14: =Investment_Master!Q14/5 -> 2349728.3 | K14: =NPV(D14,F14:J14)+E14 -> -602681.15 | L14: =IFERROR(IRR(E14:J14),0) -> 0.074870558 | M14: =Investment_Master!V14 -> 4.0472765
A15: =Investment_Master!A15 -> INV-011 | B15: =Investment_Master!B15 -> Premium Product Line – Central | C15: =Investment_Master!J15 -> 24030000 | D15: =Investment_Master!Y15 -> 0.12 | E15: =-C15 -> -24030000 | F15: =Investment_Master!Q15/5 -> 5108184.9 | G15: =Investment_Master!Q15/5 -> 5108184.9 | H15: =Investment_Master!Q15/5 -> 5108184.9 | I15: =Investment_Master!Q15/5 -> 5108184.9 | J15: =Investment_Master!Q15/5 -> 5108184.9 | K15: =NPV(D15,F15:J15)+E15 -> -5616136.8 | L15: =IFERROR(IRR(E15:J15),0) -> 0.020676798 | M15: =Investment_Master!V15 -> 4.704215
A16: =Investment_Master!A16 -> INV-012 | B16: =Investment_Master!B16 -> Tier-2 City Expansion – South | C16: =Investment_Master!J16 -> 29770000 | D16: =Investment_Master!Y16 -> 0.09 | E16: =-C16 -> -29770000 | F16: =Investment_Master!Q16/5 -> 7009433.3 | G16: =Investment_Master!Q16/5 -> 7009433.3 | H16: =Investment_Master!Q16/5 -> 7009433.3 | I16: =Investment_Master!Q16/5 -> 7009433.3 | J16: =Investment_Master!Q16/5 -> 7009433.3 | K16: =NPV(D16,F16:J16)+E16 -> -2505748.8 | L16: =IFERROR(IRR(E16:J16),0) -> 0.056985528 | M16: =Investment_Master!V16 -> 4.2471336
... A154: =Investment_Master!A154 -> INV-150 | B154: =Investment_Master!B154 -> RPA Finance Rollout – East | C154: =Investment_Master!J154 -> 17760000 | D154: =Investment_Master!Y154 -> 0.11 | E154: =-C154 -> -17760000 | F154: =Investment_Master!Q154/5 -> 4230657 | G154: =Investment_Master!Q154/5 -> 4230657 | H154: =Investment_Master!Q154/5 -> 4230657 | I154: =Investment_Master!Q154/5 -> 4230657 | J154: =Investment_Master!Q154/5 -> 4230657 | K154: =NPV(D154,F154:J154)+E154 -> -2123927.5 | L154: =IFERROR(IRR(E154:J154),0) -> 0.061263036 | M154: =Investment_Master!V154 -> 4.1979296

Sheet Budget_vs_Actual
A1: Budget vs Actual Investment
A2: Capital spending control and cost-overrun monitoring
A4: Investment_ID | B4: Investment_Name | C4: Category | D4: Department | E4: Budgeted Investment | F4: Actual Investment | G4: Variance | H4: Variance % | I4: Status
A5: =Investment_Master!A5 -> INV-001 | B5: =Investment_Master!B5 -> ERP Cloud Migration – Central | C5: =Investment_Master!C5 -> Technology | D5: =Investment_Master!D5 -> HR | E5: =Investment_Master!K5 -> 36270000 | F5: =Investment_Master!J5 -> 36250000 | G5: =F5-E5 -> -20000 | H5: =IFERROR(G5/E5,0) -> -0.00055141991 | I5: =IF(H5<=0,"Within Budget",IF(H5<=5%,"Moderate Overrun","Significant Overrun")) -> Within Budget
A6: =Investment_Master!A6 -> INV-002 | B6: =Investment_Master!B6 -> Brand Repositioning – South | C6: =Investment_Master!C6 -> Marketing | D6: =Investment_Master!D6 -> Supply Chain | E6: =Investment_Master!K6 -> 8460000 | F6: =Investment_Master!J6 -> 8020000 | G6: =F6-E6 -> -440000 | H6: =IFERROR(G6/E6,0) -> -0.052009456 | I6: =IF(H6<=0,"Within Budget",IF(H6<=5%,"Moderate Overrun","Significant Overrun")) -> Within Budget
A7: =Investment_Master!A7 -> INV-003 | B7: =Investment_Master!B7 -> Premium Product Line – West | C7: =Investment_Master!C7 -> Product Development | D7: =Investment_Master!D7 -> Operations | E7: =Investment_Master!K7 -> 36480000 | F7: =Investment_Master!J7 -> 35540000 | G7: =F7-E7 -> -940000 | H7: =IFERROR(G7/E7,0) -> -0.025767544 | I7: =IF(H7<=0,"Within Budget",IF(H7<=5%,"Moderate Overrun","Significant Overrun")) -> Within Budget
A8: =Investment_Master!A8 -> INV-004 | B8: =Investment_Master!B8 -> Tier-2 City Expansion – North | C8: =Investment_Master!C8 -> Expansion | D8: =Investment_Master!D8 -> Finance | E8: =Investment_Master!K8 -> 24320000 | F8: =Investment_Master!J8 -> 23090000 | G8: =F8-E8 -> -1230000 | H8: =IFERROR(G8/E8,0) -> -0.050575658 | I8: =IF(H8<=0,"Within Budget",IF(H8<=5%,"Moderate Overrun","Significant Overrun")) -> Within Budget
A9: =Investment_Master!A9 -> INV-005 | B9: =Investment_Master!B9 -> Automated Packaging Line – East | C9: =Investment_Master!C9 -> Equipment | D9: =Investment_Master!D9 -> Sales | E9: =Investment_Master!K9 -> 30250000 | F9: =Investment_Master!J9 -> 31290000 | G9: =F9-E9 -> 1040000 | H9: =IFERROR(G9/E9,0) -> 0.034380165 | I9: =IF(H9<=0,"Within Budget",IF(H9<=5%,"Moderate Overrun","Significant Overrun")) -> Moderate Overrun
A10: =Investment_Master!A10 -> INV-006 | B10: =Investment_Master!B10 -> RPA Finance Rollout – Central | C10: =Investment_Master!C10 -> Automation | D10: =Investment_Master!D10 -> IT | E10: =Investment_Master!K10 -> 17490000 | F10: =Investment_Master!J10 -> 18900000 | G10: =F10-E10 -> 1410000 | H10: =IFERROR(G10/E10,0) -> 0.080617496 | I10: =IF(H10<=0,"Within Budget",IF(H10<=5%,"Moderate Overrun","Significant Overrun")) -> Significant Overrun
A11: =Investment_Master!A11 -> INV-007 | B11: =Investment_Master!B11 -> Leadership Development – South | C11: =Investment_Master!C11 -> Training | D11: =Investment_Master!D11 -> Product | E11: =Investment_Master!K11 -> 12170000 | F11: =Investment_Master!J11 -> 13230000 | G11: =F11-E11 -> 1060000 | H11: =IFERROR(G11/E11,0) -> 0.087099425 | I11: =IF(H11<=0,"Within Budget",IF(H11<=5%,"Moderate Overrun","Significant Overrun")) -> Significant Overrun
A12: =Investment_Master!A12 -> INV-008 | B12: =Investment_Master!B12 -> Plant Utility Upgrade – West | C12: =Investment_Master!C12 -> Infrastructure | D12: =Investment_Master!D12 -> Marketing | E12: =Investment_Master!K12 -> 16370000 | F12: =Investment_Master!J12 -> 17620000 | G12: =F12-E12 -> 1250000 | H12: =IFERROR(G12/E12,0) -> 0.076359194 | I12: =IF(H12<=0,"Within Budget",IF(H12<=5%,"Moderate Overrun","Significant Overrun")) -> Significant Overrun
A13: =Investment_Master!A13 -> INV-009 | B13: =Investment_Master!B13 -> ERP Cloud Migration – North | C13: =Investment_Master!C13 -> Technology | D13: =Investment_Master!D13 -> HR | E13: =Investment_Master!K13 -> 21430000 | F13: =Investment_Master!J13 -> 20840000 | G13: =F13-E13 -> -590000 | H13: =IFERROR(G13/E13,0) -> -0.027531498 | I13: =IF(H13<=0,"Within Budget",IF(H13<=5%,"Moderate Overrun","Significant Overrun")) -> Within Budget
A14: =Investment_Master!A14 -> INV-010 | B14: =Investment_Master!B14 -> Brand Repositioning – East | C14: =Investment_Master!C14 -> Marketing | D14: =Investment_Master!D14 -> Supply Chain | E14: =Investment_Master!K14 -> 9850000 | F14: =Investment_Master!J14 -> 9510000 | G14: =F14-E14 -> -340000 | H14: =IFERROR(G14/E14,0) -> -0.034517766 | I14: =IF(H14<=0,"Within Budget",IF(H14<=5%,"Moderate Overrun","Significant Overrun")) -> Within Budget
A15: =Investment_Master!A15 -> INV-011 | B15: =Investment_Master!B15 -> Premium Product Line – Central | C15: =Investment_Master!C15 -> Product Development | D15: =Investment_Master!D15 -> Operations | E15: =Investment_Master!K15 -> 25610000 | F15: =Investment_Master!J15 -> 24030000 | G15: =F15-E15 -> -1580000 | H15: =IFERROR(G15/E15,0) -> -0.061694651 | I15: =IF(H15<=0,"Within Budget",IF(H15<=5%,"Moderate Overrun","Significant Overrun")) -> Within Budget
A16: =Investment_Master!A16 -> INV-012 | B16: =Investment_Master!B16 -> Tier-2 City Expansion – South | C16: =Investment_Master!C16 -> Expansion | D16: =Investment_Master!D16 -> Finance | E16: =Investment_Master!K16 -> 30060000 | F16: =Investment_Master!J16 -> 29770000 | G16: =F16-E16 -> -290000 | H16: =IFERROR(G16/E16,0) -> -0.0096473719 | I16: =IF(H16<=0,"Within Budget",IF(H16<=5%,"Moderate Overrun","Significant Overrun")) -> Within Budget
... A154: =Investment_Master!A154 -> INV-150 | B154: =Investment_Master!B154 -> RPA Finance Rollout – East | C154: =Investment_Master!C154 -> Automation | D154: =Investment_Master!D154 -> IT | E154: =Investment_Master!K154 -> 16410000 | F154: =Investment_Master!J154 -> 17760000 | G154: =F154-E154 -> 1350000 | H154: =IFERROR(G154/E154,0) -> 0.08226691 | I154: =IF(H154<=0,"Within Budget",IF(H154<=5%,"Moderate Overrun","Significant Overrun")) -> Significant Overrun

Sheet Department_Analysis
A1: Department & Category Analysis
A2: Aggregated capital allocation, financial benefit and performance
A4: Department | B4: Total Investment | C4: Actual Revenue | D4: Cost Savings | E4: Net Benefit | F4: ROI | G4: Avg NPV | H4: Avg Payback | I4: Avg Risk Score | J4: Investments
A5: Sales | B5: =SUMIF(Investment_Master!$D$5:$D$154,A5,Investment_Master!$J$5:$J$154) -> 504680000 | C5: =SUMIF(Investment_Master!$D$5:$D$154,A5,Investment_Master!$M$5:$M$154) -> 5.1990048e+08 | D5: =SUMIF(Investment_Master!$D$5:$D$154,A5,Investment_Master!$O$5:$O$154) -> 60894507 | E5: =C5+D5-B5 -> 76114984 | F5: =IFERROR(E5/B5,0) -> 0.15081831 | G5: =AVERAGEIF(Investment_Master!$D$5:$D$154,A5,Investment_Master!$W$5:$W$154) -> -3869214.5 | H5: =AVERAGEIF(Investment_Master!$D$5:$D$154,A5,Investment_Master!$V$5:$V$154) -> 4.3511502 | I5: =IFERROR(AVERAGE(IF(Investment_Master!$D$5:$D$154=A5,IF(Investment_Master!$AA$5:$AA$154="Low",1,IF(Investment_Master!$AA$5:$AA$154="Medium",2,3)))),0) -> 0 | J5: =COUNTIF(Investment_Master!$D$5:$D$154,A5) -> 19
A6: Marketing | B6: =SUMIF(Investment_Master!$D$5:$D$154,A6,Investment_Master!$J$5:$J$154) -> 692480000 | C6: =SUMIF(Investment_Master!$D$5:$D$154,A6,Investment_Master!$M$5:$M$154) -> 6.6262894e+08 | D6: =SUMIF(Investment_Master!$D$5:$D$154,A6,Investment_Master!$O$5:$O$154) -> 94809760 | E6: =C6+D6-B6 -> 64958701 | F6: =IFERROR(E6/B6,0) -> 0.093805888 | G6: =AVERAGEIF(Investment_Master!$D$5:$D$154,A6,Investment_Master!$W$5:$W$154) -> -7283725.7 | H6: =AVERAGEIF(Investment_Master!$D$5:$D$154,A6,Investment_Master!$V$5:$V$154) -> 4.6041177 | I6: =IFERROR(AVERAGE(IF(Investment_Master!$D$5:$D$154=A6,IF(Investment_Master!$AA$5:$AA$154="Low",1,IF(Investment_Master!$AA$5:$AA$154="Medium",2,3)))),0) -> 0 | J6: =COUNTIF(Investment_Master!$D$5:$D$154,A6) -> 18
A7: Operations | B7: =SUMIF(Investment_Master!$D$5:$D$154,A7,Investment_Master!$J$5:$J$154) -> 535570000 | C7: =SUMIF(Investment_Master!$D$5:$D$154,A7,Investment_Master!$M$5:$M$154) -> 5.1099076e+08 | D7: =SUMIF(Investment_Master!$D$5:$D$154,A7,Investment_Master!$O$5:$O$154) -> 61869835 | E7: =C7+D7-B7 -> 37290592 | F7: =IFERROR(E7/B7,0) -> 0.069627859 | G7: =AVERAGEIF(Investment_Master!$D$5:$D$154,A7,Investment_Master!$W$5:$W$154) -> -5716968.8 | H7: =AVERAGEIF(Investment_Master!$D$5:$D$154,A7,Investment_Master!$V$5:$V$154) -> 4.6947801 | I7: =IFERROR(AVERAGE(IF(Investment_Master!$D$5:$D$154=A7,IF(Investment_Master!$AA$5:$AA$154="Low",1,IF(Investment_Master!$AA$5:$AA$154="Medium",2,3)))),0) -> 2 | J7: =COUNTIF(Investment_Master!$D$5:$D$154,A7) -> 19
A8: IT | B8: =SUMIF(Investment_Master!$D$5:$D$154,A8,Investment_Master!$J$5:$J$154) -> 427770000 | C8: =SUMIF(Investment_Master!$D$5:$D$154,A8,Investment_Master!$M$5:$M$154) -> 4.7758103e+08 | D8: =SUMIF(Investment_Master!$D$5:$D$154,A8,Investment_Master!$O$5:$O$154) -> 45805408 | E8: =C8+D8-B8 -> 95616440 | F8: =IFERROR(E8/B8,0) -> 0.22352301 | G8: =AVERAGEIF(Investment_Master!$D$5:$D$154,A8,Investment_Master!$W$5:$W$154) -> -1940787.2 | H8: =AVERAGEIF(Investment_Master!$D$5:$D$154,A8,Investment_Master!$V$5:$V$154) -> 4.0797209 | I8: =IFERROR(AVERAGE(IF(Investment_Master!$D$5:$D$154=A8,IF(Investment_Master!$AA$5:$AA$154="Low",1,IF(Investment_Master!$AA$5:$AA$154="Medium",2,3)))),0) -> 0 | J8: =COUNTIF(Investment_Master!$D$5:$D$154,A8) -> 19
A9: HR | B9: =SUMIF(Investment_Master!$D$5:$D$154,A9,Investment_Master!$J$5:$J$154) -> 446040000 | C9: =SUMIF(Investment_Master!$D$5:$D$154,A9,Investment_Master!$M$5:$M$154) -> 4.8255296e+08 | D9: =SUMIF(Investment_Master!$D$5:$D$154,A9,Investment_Master!$O$5:$O$154) -> 57791555 | E9: =C9+D9-B9 -> 94304516 | F9: =IFERROR(E9/B9,0) -> 0.21142614 | G9: =AVERAGEIF(Investment_Master!$D$5:$D$154,A9,Investment_Master!$W$5:$W$154) -> -2353924.4 | H9: =AVERAGEIF(Investment_Master!$D$5:$D$154,A9,Investment_Master!$V$5:$V$154) -> 4.1102385 | I9: =IFERROR(AVERAGE(IF(Investment_Master!$D$5:$D$154=A9,IF(Investment_Master!$AA$5:$AA$154="Low",1,IF(Investment_Master!$AA$5:$AA$154="Medium",2,3)))),0) -> 0 | J9: =COUNTIF(Investment_Master!$D$5:$D$154,A9) -> 19
A10: Finance | B10: =SUMIF(Investment_Master!$D$5:$D$154,A10,Investment_Master!$J$5:$J$154) -> 781850000 | C10: =SUMIF(Investment_Master!$D$5:$D$154,A10,Investment_Master!$M$5:$M$154) -> 7.6581066e+08 | D10: =SUMIF(Investment_Master!$D$5:$D$154,A10,Investment_Master!$O$5:$O$154) -> 1.0495733e+08 | E10: =C10+D10-B10 -> 88917994 | F10: =IFERROR(E10/B10,0) -> 0.11372769 | G10: =AVERAGEIF(Investment_Master!$D$5:$D$154,A10,Investment_Master!$W$5:$W$154) -> -5497538.7 | H10: =AVERAGEIF(Investment_Master!$D$5:$D$154,A10,Investment_Master!$V$5:$V$154) -> 4.4828042 | I10: =IFERROR(AVERAGE(IF(Investment_Master!$D$5:$D$154=A10,IF(Investment_Master!$AA$5:$AA$154="Low",1,IF(Investment_Master!$AA$5:$AA$154="Medium",2,3)))),0) -> 0 | J10: =COUNTIF(Investment_Master!$D$5:$D$154,A10) -> 19
A11: Product | B11: =SUMIF(Investment_Master!$D$5:$D$154,A11,Investment_Master!$J$5:$J$154) -> 133110000 | C11: =SUMIF(Investment_Master!$D$5:$D$154,A11,Investment_Master!$M$5:$M$154) -> 1.156761e+08 | D11: =SUMIF(Investment_Master!$D$5:$D$154,A11,Investment_Master!$O$5:$O$154) -> 15877014 | E11: =C11+D11-B11 -> -1556883.8 | F11: =IFERROR(E11/B11,0) -> -0.01169622 | G11: =AVERAGEIF(Investment_Master!$D$5:$D$154,A11,Investment_Master!$W$5:$W$154) -> -1954289.1 | H11: =AVERAGEIF(Investment_Master!$D$5:$D$154,A11,Investment_Master!$V$5:$V$154) -> 5.1090978 | I11: =IFERROR(AVERAGE(IF(Investment_Master!$D$5:$D$154=A11,IF(Investment_Master!$AA$5:$AA$154="Low",1,IF(Investment_Master!$AA$5:$AA$154="Medium",2,3)))),0) -> 1 | J11: =COUNTIF(Investment_Master!$D$5:$D$154,A11) -> 18
A12: Supply Chain | B12: =SUMIF(Investment_Master!$D$5:$D$154,A12,Investment_Master!$J$5:$J$154) -> 265060000 | C12: =SUMIF(Investment_Master!$D$5:$D$154,A12,Investment_Master!$M$5:$M$154) -> 2.768153e+08 | D12: =SUMIF(Investment_Master!$D$5:$D$154,A12,Investment_Master!$O$5:$O$154) -> 35636030 | E12: =C12+D12-B12 -> 47391334 | F12: =IFERROR(E12/B12,0) -> 0.17879474 | G12: =AVERAGEIF(Investment_Master!$D$5:$D$154,A12,Investment_Master!$W$5:$W$154) -> -1736240.2 | H12: =AVERAGEIF(Investment_Master!$D$5:$D$154,A12,Investment_Master!$V$5:$V$154) -> 4.2621845 | I12: =IFERROR(AVERAGE(IF(Investment_Master!$D$5:$D$154=A12,IF(Investment_Master!$AA$5:$AA$154="Low",1,IF(Investment_Master!$AA$5:$AA$154="Medium",2,3)))),0) -> 0 | J12: =COUNTIF(Investment_Master!$D$5:$D$154,A12) -> 19
A15: Category Analysis
A16: Category | B16: Total Investment | C16: Revenue | D16: Savings | E16: Net Benefit | F16: ROI | G16: Avg NPV | H16: Avg Payback | I16: Avg Score
A17: Technology | B17: =SUMIF(Investment_Master!$C$5:$C$154,A17,Investment_Master!$J$5:$J$154) -> 446040000 | C17: =SUMIF(Investment_Master!$C$5:$C$154,A17,Investment_Master!$M$5:$M$154) -> 4.8255296e+08 | D17: =SUMIF(Investment_Master!$C$5:$C$154,A17,Investment_Master!$O$5:$O$154) -> 57791555 | E17: =C17+D17-B17 -> 94304516 | F17: =IFERROR(E17/B17,0) -> 0.21142614 | G17: =AVERAGEIF(Investment_Master!$C$5:$C$154,A17,Investment_Master!$W$5:$W$154) -> -2353924.4 | H17: =AVERAGEIF(Investment_Master!$C$5:$C$154,A17,Investment_Master!$V$5:$V$154) -> 4.1102385 | I17: =AVERAGEIF(Investment_Master!$C$5:$C$154,A17,Investment_Master!$AG$5:$AG$154) -> 61.561269
